2025-08-07 15:23:46,152 INFO: Chatbot startup [in C:\Users\eylul\chatbot-flask\app\__init__.py:36]
2025-08-07 15:24:01,673 ERROR: Failed to connect to database at localhost:3307 - 2003 (HY000): Can't connect to MySQL server on 'localhost:3307' (10061) [in C:\Users\eylul\chatbot-flask\app\db_utils.py:53]
2025-08-07 15:24:01,674 ERROR: Exception on /login [POST] [in C:\Users\eylul\AppData\Local\Programs\Python\Python313\Lib\site-packages\flask\app.py:875]
Traceback (most recent call last):
  File "C:\Users\eylul\AppData\Local\Programs\Python\Python313\Lib\site-packages\mysql\connector\connection_cext.py", line 354, in _open_connection
    self._cmysql.connect(**cnx_kwargs)
    ~~~~~~~~~~~~~~~~~~~~^^^^^^^^^^^^^^
_mysql_connector.MySQLInterfaceError: Can't connect to MySQL server on 'localhost:3307' (10061)

The above exception was the direct cause of the following exception:

Traceback (most recent call last):
  File "C:\Users\eylul\chatbot-flask\app\db_utils.py", line 38, in get_db_connection
    connection = mysql.connector.connect(
        host=db_host,
    ...<7 lines>...
        time_zone='+00:00'
    )
  File "C:\Users\eylul\AppData\Local\Programs\Python\Python313\Lib\site-packages\mysql\connector\pooling.py", line 322, in connect
    return CMySQLConnection(*args, **kwargs)
  File "C:\Users\eylul\AppData\Local\Programs\Python\Python313\Lib\site-packages\mysql\connector\connection_cext.py", line 142, in __init__
    self.connect(**kwargs)
    ~~~~~~~~~~~~^^^^^^^^^^
  File "C:\Users\eylul\AppData\Local\Programs\Python\Python313\Lib\site-packages\mysql\connector\abstracts.py", line 1604, in connect
    self._open_connection()
    ~~~~~~~~~~~~~~~~~~~~~^^
  File "C:\Users\eylul\AppData\Local\Programs\Python\Python313\Lib\site-packages\mysql\connector\connection_cext.py", line 360, in _open_connection
    raise get_mysql_exception(
        err.errno, msg=err.msg, sqlstate=err.sqlstate
    ) from err
mysql.connector.errors.DatabaseError: 2003 (HY000): Can't connect to MySQL server on 'localhost:3307' (10061)

The above exception was the direct cause of the following exception:

Traceback (most recent call last):
  File "C:\Users\eylul\AppData\Local\Programs\Python\Python313\Lib\site-packages\flask\app.py", line 1511, in wsgi_app
    response = self.full_dispatch_request()
  File "C:\Users\eylul\AppData\Local\Programs\Python\Python313\Lib\site-packages\flask\app.py", line 919, in full_dispatch_request
    rv = self.handle_user_exception(e)
  File "C:\Users\eylul\AppData\Local\Programs\Python\Python313\Lib\site-packages\flask\app.py", line 917, in full_dispatch_request
    rv = self.dispatch_request()
  File "C:\Users\eylul\AppData\Local\Programs\Python\Python313\Lib\site-packages\flask\app.py", line 902, in dispatch_request
    return self.ensure_sync(self.view_functions[rule.endpoint])(**view_args)  # type: ignore[no-any-return]
           ~~~~~~~~~~~~~~~~~~~~~~~~~~~~~~~~~~~~~~~~~~~~~~~~~~~~^^^^^^^^^^^^^
  File "C:\Users\eylul\chatbot-flask\app\routes.py", line 198, in login
    conn = get_db_connection()
  File "C:\Users\eylul\chatbot-flask\app\db_utils.py", line 54, in get_db_connection
    raise mysql.connector.Error(error_msg) from e
mysql.connector.errors.Error: Failed to connect to database at localhost:3307 - 2003 (HY000): Can't connect to MySQL server on 'localhost:3307' (10061)
2025-08-07 15:24:01,696 ERROR: 500 error: 500 Internal Server Error: The server encountered an internal error and was unable to complete your request. Either the server is overloaded or there is an error in the application. [in C:\Users\eylul\chatbot-flask\app\__init__.py:49]
2025-08-07 15:24:03,929 ERROR: Failed to connect to database at localhost:3307 - 2003 (HY000): Can't connect to MySQL server on 'localhost:3307' (10061) [in C:\Users\eylul\chatbot-flask\app\db_utils.py:53]
2025-08-07 15:24:03,930 ERROR: Exception on /login [POST] [in C:\Users\eylul\AppData\Local\Programs\Python\Python313\Lib\site-packages\flask\app.py:875]
Traceback (most recent call last):
  File "C:\Users\eylul\AppData\Local\Programs\Python\Python313\Lib\site-packages\mysql\connector\connection_cext.py", line 354, in _open_connection
    self._cmysql.connect(**cnx_kwargs)
    ~~~~~~~~~~~~~~~~~~~~^^^^^^^^^^^^^^
_mysql_connector.MySQLInterfaceError: Can't connect to MySQL server on 'localhost:3307' (10061)

The above exception was the direct cause of the following exception:

Traceback (most recent call last):
  File "C:\Users\eylul\chatbot-flask\app\db_utils.py", line 38, in get_db_connection
    connection = mysql.connector.connect(
        host=db_host,
    ...<7 lines>...
        time_zone='+00:00'
    )
  File "C:\Users\eylul\AppData\Local\Programs\Python\Python313\Lib\site-packages\mysql\connector\pooling.py", line 322, in connect
    return CMySQLConnection(*args, **kwargs)
  File "C:\Users\eylul\AppData\Local\Programs\Python\Python313\Lib\site-packages\mysql\connector\connection_cext.py", line 142, in __init__
    self.connect(**kwargs)
    ~~~~~~~~~~~~^^^^^^^^^^
  File "C:\Users\eylul\AppData\Local\Programs\Python\Python313\Lib\site-packages\mysql\connector\abstracts.py", line 1604, in connect
    self._open_connection()
    ~~~~~~~~~~~~~~~~~~~~~^^
  File "C:\Users\eylul\AppData\Local\Programs\Python\Python313\Lib\site-packages\mysql\connector\connection_cext.py", line 360, in _open_connection
    raise get_mysql_exception(
        err.errno, msg=err.msg, sqlstate=err.sqlstate
    ) from err
mysql.connector.errors.DatabaseError: 2003 (HY000): Can't connect to MySQL server on 'localhost:3307' (10061)

The above exception was the direct cause of the following exception:

Traceback (most recent call last):
  File "C:\Users\eylul\AppData\Local\Programs\Python\Python313\Lib\site-packages\flask\app.py", line 1511, in wsgi_app
    response = self.full_dispatch_request()
  File "C:\Users\eylul\AppData\Local\Programs\Python\Python313\Lib\site-packages\flask\app.py", line 919, in full_dispatch_request
    rv = self.handle_user_exception(e)
  File "C:\Users\eylul\AppData\Local\Programs\Python\Python313\Lib\site-packages\flask\app.py", line 917, in full_dispatch_request
    rv = self.dispatch_request()
  File "C:\Users\eylul\AppData\Local\Programs\Python\Python313\Lib\site-packages\flask\app.py", line 902, in dispatch_request
    return self.ensure_sync(self.view_functions[rule.endpoint])(**view_args)  # type: ignore[no-any-return]
           ~~~~~~~~~~~~~~~~~~~~~~~~~~~~~~~~~~~~~~~~~~~~~~~~~~~~^^^^^^^^^^^^^
  File "C:\Users\eylul\chatbot-flask\app\routes.py", line 198, in login
    conn = get_db_connection()
  File "C:\Users\eylul\chatbot-flask\app\db_utils.py", line 54, in get_db_connection
    raise mysql.connector.Error(error_msg) from e
mysql.connector.errors.Error: Failed to connect to database at localhost:3307 - 2003 (HY000): Can't connect to MySQL server on 'localhost:3307' (10061)
2025-08-07 15:24:03,933 ERROR: 500 error: 500 Internal Server Error: The server encountered an internal error and was unable to complete your request. Either the server is overloaded or there is an error in the application. [in C:\Users\eylul\chatbot-flask\app\__init__.py:49]
